Error in file(file, "rt") : cannot open the connection
Calls: read.table -> file
In addition: Warning message:
In file(file, "rt") :
  cannot open file 'owncloud/data/aumza/files/test_run/data/input/file_phylum_count.txt': No such file or directory
Execution halted
